Workbook

Sheet Fase de Grupos
A1: Copa do Mundo 2026 - Controle de Boloes - Fase de Grupos
A2: Grupo | B2: Jogo | C2: Mandante | D2: Visitante | E2: Zap | G2: Cli | I2: Polla | K2: Real | M2: Pts Zap | N2: Pts Cli | O2: Pts Polla | P2: Obs
E3: M | F3: V | G3: M | H3: V | I3: M | J3: V | K3: M | L3: V
A4: Grupo A
A5: A | B5: 1 | C5: MEX | D5: AFS | E5: 2 | F5: 0 | G5: 2 | H5: 1 | I5: 1 | J5: 0 | K5: 2 | L5: 0 | M5: =IF(OR($K5="",$L5="",$E5="",$F5=""),"",IF($E5=$F5,IF($K5=$L5,IF($E5=$K5,10,6),0),IF(OR($K5=$L5,SIGN($E5-$F5)<>SIGN($K5-$L5)),0,IF(AND($E5=$K5,$F5=$L5),10,IF(($E5-$F5)=($K5-$L5),6,IF(MAX($E5,$F5)=MAX($K5,$L5),5,IF(MIN($E5,$F5)=MIN($K5,$L5),4,3))))))) | N5: =IF(OR($K5="",$L5="",$G5="",$H5=""),"",IF(AND($G5=$K5,$H5=$L5),5+IF(($K5+$L5)>=6,2,IF(($K5+$L5)=5,1,0)),IF(AND($G5=$H5,$K5=$L5),3,IF(AND($G5<>$H5,$K5<>$L5,SIGN($G5-$H5)=SIGN($K5-$L5)),2,0)))) | O5: =IF(OR($K5="",$L5="",$I5="",$J5=""),"",IF(AND($I5=$K5,$J5=$L5),3,IF(SIGN($I5-$J5)=SIGN($K5-$L5),1,0)))
A6: A | B6: 2 | C6: COR | D6: CZE | E6: 2 | F6: 1 | G6: 2 | H6: 1 | I6: 1 | J6: 1 | K6: 2 | L6: 1 | M6: =IF(OR($K6="",$L6="",$E6="",$F6=""),"",IF($E6=$F6,IF($K6=$L6,IF($E6=$K6,10,6),0),IF(OR($K6=$L6,SIGN($E6-$F6)<>SIGN($K6-$L6)),0,IF(AND($E6=$K6,$F6=$L6),10,IF(($E6-$F6)=($K6-$L6),6,IF(MAX($E6,$F6)=MAX($K6,$L6),5,IF(MIN($E6,$F6)=MIN($K6,$L6),4,3))))))) | N6: =IF(OR($K6="",$L6="",$G6="",$H6=""),"",IF(AND($G6=$K6,$H6=$L6),5+IF(($K6+$L6)>=6,2,IF(($K6+$L6)=5,1,0)),IF(AND($G6=$H6,$K6=$L6),3,IF(AND($G6<>$H6,$K6<>$L6,SIGN($G6-$H6)=SIGN($K6-$L6)),2,0)))) | O6: =IF(OR($K6="",$L6="",$I6="",$J6=""),"",IF(AND($I6=$K6,$J6=$L6),3,IF(SIGN($I6-$J6)=SIGN($K6-$L6),1,0)))
A7: A | B7: 3 | C7: CZE | D7: AFS | E7: 2 | F7: 1 | G7: 2 | H7: 1 | I7: 1 | J7: 0 | M7: =IF(OR($K7="",$L7="",$E7="",$F7=""),"",IF($E7=$F7,IF($K7=$L7,IF($E7=$K7,10,6),0),IF(OR($K7=$L7,SIGN($E7-$F7)<>SIGN($K7-$L7)),0,IF(AND($E7=$K7,$F7=$L7),10,IF(($E7-$F7)=($K7-$L7),6,IF(MAX($E7,$F7)=MAX($K7,$L7),5,IF(MIN($E7,$F7)=MIN($K7,$L7),4,3))))))) | N7: =IF(OR($K7="",$L7="",$G7="",$H7=""),"",IF(AND($G7=$K7,$H7=$L7),5+IF(($K7+$L7)>=6,2,IF(($K7+$L7)=5,1,0)),IF(AND($G7=$H7,$K7=$L7),3,IF(AND($G7<>$H7,$K7<>$L7,SIGN($G7-$H7)=SIGN($K7-$L7)),2,0)))) | O7: =IF(OR($K7="",$L7="",$I7="",$J7=""),"",IF(AND($I7=$K7,$J7=$L7),3,IF(SIGN($I7-$J7)=SIGN($K7-$L7),1,0)))
A8: A | B8: 4 | C8: MEX | D8: COR | E8: 2 | F8: 1 | G8: 2 | H8: 1 | I8: 1 | J8: 1 | M8: =IF(OR($K8="",$L8="",$E8="",$F8=""),"",IF($E8=$F8,IF($K8=$L8,IF($E8=$K8,10,6),0),IF(OR($K8=$L8,SIGN($E8-$F8)<>SIGN($K8-$L8)),0,IF(AND($E8=$K8,$F8=$L8),10,IF(($E8-$F8)=($K8-$L8),6,IF(MAX($E8,$F8)=MAX($K8,$L8),5,IF(MIN($E8,$F8)=MIN($K8,$L8),4,3))))))) | N8: =IF(OR($K8="",$L8="",$G8="",$H8=""),"",IF(AND($G8=$K8,$H8=$L8),5+IF(($K8+$L8)>=6,2,IF(($K8+$L8)=5,1,0)),IF(AND($G8=$H8,$K8=$L8),3,IF(AND($G8<>$H8,$K8<>$L8,SIGN($G8-$H8)=SIGN($K8-$L8)),2,0)))) | O8: =IF(OR($K8="",$L8="",$I8="",$J8=""),"",IF(AND($I8=$K8,$J8=$L8),3,IF(SIGN($I8-$J8)=SIGN($K8-$L8),1,0)))
A9: A | B9: 5 | C9: CZE | D9: MEX | E9: 2 | F9: 1 | G9: 1 | H9: 2 | I9: 1 | J9: 1 | M9: =IF(OR($K9="",$L9="",$E9="",$F9=""),"",IF($E9=$F9,IF($K9=$L9,IF($E9=$K9,10,6),0),IF(OR($K9=$L9,SIGN($E9-$F9)<>SIGN($K9-$L9)),0,IF(AND($E9=$K9,$F9=$L9),10,IF(($E9-$F9)=($K9-$L9),6,IF(MAX($E9,$F9)=MAX($K9,$L9),5,IF(MIN($E9,$F9)=MIN($K9,$L9),4,3))))))) | N9: =IF(OR($K9="",$L9="",$G9="",$H9=""),"",IF(AND($G9=$K9,$H9=$L9),5+IF(($K9+$L9)>=6,2,IF(($K9+$L9)=5,1,0)),IF(AND($G9=$H9,$K9=$L9),3,IF(AND($G9<>$H9,$K9<>$L9,SIGN($G9-$H9)=SIGN($K9-$L9)),2,0)))) | O9: =IF(OR($K9="",$L9="",$I9="",$J9=""),"",IF(AND($I9=$K9,$J9=$L9),3,IF(SIGN($I9-$J9)=SIGN($K9-$L9),1,0)))
A10: A | B10: 6 | C10: AFS | D10: COR | E10: 1 | F10: 2 | G10: 1 | H10: 2 | I10: 0 | J10: 1 | M10: =IF(OR($K10="",$L10="",$E10="",$F10=""),"",IF($E10=$F10,IF($K10=$L10,IF($E10=$K10,10,6),0),IF(OR($K10=$L10,SIGN($E10-$F10)<>SIGN($K10-$L10)),0,IF(AND($E10=$K10,$F10=$L10),10,IF(($E10-$F10)=($K10-$L10),6,IF(MAX($E10,$F10)=MAX($K10,$L10),5,IF(MIN($E10,$F10)=MIN($K10,$L10),4,3))))))) | N10: =IF(OR($K10="",$L10="",$G10="",$H10=""),"",IF(AND($G10=$K10,$H10=$L10),5+IF(($K10+$L10)>=6,2,IF(($K10+$L10)=5,1,0)),IF(AND($G10=$H10,$K10=$L10),3,IF(AND($G10<>$H10,$K10<>$L10,SIGN($G10-$H10)=SIGN($K10-$L10)),2,0)))) | O10: =IF(OR($K10="",$L10="",$I10="",$J10=""),"",IF(AND($I10=$K10,$J10=$L10),3,IF(SIGN($I10-$J10)=SIGN($K10-$L10),1,0)))
A11: Grupo B
A12: B | B12: 7 | C12: CAN | D12: BOS | E12: 2 | F12: 0 | G12: 2 | H12: 0 | I12: 1 | J12: 0 | M12: =IF(OR($K12="",$L12="",$E12="",$F12=""),"",IF($E12=$F12,IF($K12=$L12,IF($E12=$K12,10,6),0),IF(OR($K12=$L12,SIGN($E12-$F12)<>SIGN($K12-$L12)),0,IF(AND($E12=$K12,$F12=$L12),10,IF(($E12-$F12)=($K12-$L12),6,IF(MAX($E12,$F12)=MAX($K12,$L12),5,IF(MIN($E12,$F12)=MIN($K12,$L12),4,3))))))) | N12: =IF(OR($K12="",$L12="",$G12="",$H12=""),"",IF(AND($G12=$K12,$H12=$L12),5+IF(($K12+$L12)>=6,2,IF(($K12+$L12)=5,1,0)),IF(AND($G12=$H12,$K12=$L12),3,IF(AND($G12<>$H12,$K12<>$L12,SIGN($G12-$H12)=SIGN($K12-$L12)),2,0)))) | O12: =IF(OR($K12="",$L12="",$I12="",$J12=""),"",IF(AND($I12=$K12,$J12=$L12),3,IF(SIGN($I12-$J12)=SIGN($K12-$L12),1,0)))
A13: B | B13: 8 | C13: CAT | D13: SUI | E13: 0 | F13: 2 | G13: 1 | H13: 4 | I13: 0 | J13: 2 | M13: =IF(OR($K13="",$L13="",$E13="",$F13=""),"",IF($E13=$F13,IF($K13=$L13,IF($E13=$K13,10,6),0),IF(OR($K13=$L13,SIGN($E13-$F13)<>SIGN($K13-$L13)),0,IF(AND($E13=$K13,$F13=$L13),10,IF(($E13-$F13)=($K13-$L13),6,IF(MAX($E13,$F13)=MAX($K13,$L13),5,IF(MIN($E13,$F13)=MIN($K13,$L13),4,3))))))) | N13: =IF(OR($K13="",$L13="",$G13="",$H13=""),"",IF(AND($G13=$K13,$H13=$L13),5+IF(($K13+$L13)>=6,2,IF(($K13+$L13)=5,1,0)),IF(AND($G13=$H13,$K13=$L13),3,IF(AND($G13<>$H13,$K13<>$L13,SIGN($G13-$H13)=SIGN($K13-$L13)),2,0)))) | O13: =IF(OR($K13="",$L13="",$I13="",$J13=""),"",IF(AND($I13=$K13,$J13=$L13),3,IF(SIGN($I13-$J13)=SIGN($K13-$L13),1,0)))
A14: B | B14: 9 | C14: SUI | D14: BOS | E14: 2 | F14: 0 | G14: 4 | H14: 1 | I14: 2 | J14: 0 | M14: =IF(OR($K14="",$L14="",$E14="",$F14=""),"",IF($E14=$F14,IF($K14=$L14,IF($E14=$K14,10,6),0),IF(OR($K14=$L14,SIGN($E14-$F14)<>SIGN($K14-$L14)),0,IF(AND($E14=$K14,$F14=$L14),10,IF(($E14-$F14)=($K14-$L14),6,IF(MAX($E14,$F14)=MAX($K14,$L14),5,IF(MIN($E14,$F14)=MIN($K14,$L14),4,3))))))) | N14: =IF(OR($K14="",$L14="",$G14="",$H14=""),"",IF(AND($G14=$K14,$H14=$L14),5+IF(($K14+$L14)>=6,2,IF(($K14+$L14)=5,1,0)),IF(AND($G14=$H14,$K14=$L14),3,IF(AND($G14<>$H14,$K14<>$L14,SIGN($G14-$H14)=SIGN($K14-$L14)),2,0)))) | O14: =IF(OR($K14="",$L14="",$I14="",$J14=""),"",IF(AND($I14=$K14,$J14=$L14),3,IF(SIGN($I14-$J14)=SIGN($K14-$L14),1,0)))
A15: B | B15: 10 | C15: CAN | D15: CAT | E15: 2 | F15: 0 | G15: 4 | H15: 1 | I15: 2 | J15: 0 | M15: =IF(OR($K15="",$L15="",$E15="",$F15=""),"",IF($E15=$F15,IF($K15=$L15,IF($E15=$K15,10,6),0),IF(OR($K15=$L15,SIGN($E15-$F15)<>SIGN($K15-$L15)),0,IF(AND($E15=$K15,$F15=$L15),10,IF(($E15-$F15)=($K15-$L15),6,IF(MAX($E15,$F15)=MAX($K15,$L15),5,IF(MIN($E15,$F15)=MIN($K15,$L15),4,3))))))) | N15: =IF(OR($K15="",$L15="",$G15="",$H15=""),"",IF(AND($G15=$K15,$H15=$L15),5+IF(($K15+$L15)>=6,2,IF(($K15+$L15)=5,1,0)),IF(AND($G15=$H15,$K15=$L15),3,IF(AND($G15<>$H15,$K15<>$L15,SIGN($G15-$H15)=SIGN($K15-$L15)),2,0)))) | O15: =IF(OR($K15="",$L15="",$I15="",$J15=""),"",IF(AND($I15=$K15,$J15=$L15),3,IF(SIGN($I15-$J15)=SIGN($K15-$L15),1,0)))
A16: B | B16: 11 | C16: SUI | D16: CAN | E16: 2 | F16: 1 | G16: 1 | H16: 2 | I16: 1 | J16: 0 | M16: =IF(OR($K16="",$L16="",$E16="",$F16=""),"",IF($E16=$F16,IF($K16=$L16,IF($E16=$K16,10,6),0),IF(OR($K16=$L16,SIGN($E16-$F16)<>SIGN($K16-$L16)),0,IF(AND($E16=$K16,$F16=$L16),10,IF(($E16-$F16)=($K16-$L16),6,IF(MAX($E16,$F16)=MAX($K16,$L16),5,IF(MIN($E16,$F16)=MIN($K16,$L16),4,3))))))) | N16: =IF(OR($K16="",$L16="",$G16="",$H16=""),"",IF(AND($G16=$K16,$H16=$L16),5+IF(($K16+$L16)>=6,2,IF(($K16+$L16)=5,1,0)),IF(AND($G16=$H16,$K16=$L16),3,IF(AND($G16<>$H16,$K16<>$L16,SIGN($G16-$H16)=SIGN($K16-$L16)),2,0)))) | O16: =IF(OR($K16="",$L16="",$I16="",$J16=""),"",IF(AND($I16=$K16,$J16=$L16),3,IF(SIGN($I16-$J16)=SIGN($K16-$L16),1,0)))
A17: B | B17: 12 | C17: BOS | D17: CAT | E17: 2 | F17: 1 | G17: 2 | H17: 1 | I17: 1 | J17: 0 | M17: =IF(OR($K17="",$L17="",$E17="",$F17=""),"",IF($E17=$F17,IF($K17=$L17,IF($E17=$K17,10,6),0),IF(OR($K17=$L17,SIGN($E17-$F17)<>SIGN($K17-$L17)),0,IF(AND($E17=$K17,$F17=$L17),10,IF(($E17-$F17)=($K17-$L17),6,IF(MAX($E17,$F17)=MAX($K17,$L17),5,IF(MIN($E17,$F17)=MIN($K17,$L17),4,3))))))) | N17: =IF(OR($K17="",$L17="",$G17="",$H17=""),"",IF(AND($G17=$K17,$H17=$L17),5+IF(($K17+$L17)>=6,2,IF(($K17+$L17)=5,1,0)),IF(AND($G17=$H17,$K17=$L17),3,IF(AND($G17<>$H17,$K17<>$L17,SIGN($G17-$H17)=SIGN($K17-$L17)),2,0)))) | O17: =IF(OR($K17="",$L17="",$I17="",$J17=""),"",IF(AND($I17=$K17,$J17=$L17),3,IF(SIGN($I17-$J17)=SIGN($K17-$L17),1,0)))
A18: Grupo C
A19: C | B19: 13 | C19: HAI | D19: ESC | E19: 0 | F19: 2 | G19: 1 | H19: 4 | I19: 0 | J19: 2 | M19: =IF(OR($K19="",$L19="",$E19="",$F19=""),"",IF($E19=$F19,IF($K19=$L19,IF($E19=$K19,10,6),0),IF(OR($K19=$L19,SIGN($E19-$F19)<>SIGN($K19-$L19)),0,IF(AND($E19=$K19,$F19=$L19),10,IF(($E19-$F19)=($K19-$L19),6,IF(MAX($E19,$F19)=MAX($K19,$L19),5,IF(MIN($E19,$F19)=MIN($K19,$L19),4,3))))))) | N19: =IF(OR($K19="",$L19="",$G19="",$H19=""),"",IF(AND($G19=$K19,$H19=$L19),5+IF(($K19+$L19)>=6,2,IF(($K19+$L19)=5,1,0)),IF(AND($G19=$H19,$K19=$L19),3,IF(AND($G19<>$H19,$K19<>$L19,SIGN($G19-$H19)=SIGN($K19-$L19)),2,0)))) | O19: =IF(OR($K19="",$L19="",$I19="",$J19=""),"",IF(AND($I19=$K19,$J19=$L19),3,IF(SIGN($I19-$J19)=SIGN($K19-$L19),1,0)))
A20: C | B20: 14 | C20: BRA | D20: MAR | E20: 2 | F20: 1 | G20: 2 | H20: 1 | I20: 1 | J20: 0 | M20: =IF(OR($K20="",$L20="",$E20="",$F20=""),"",IF($E20=$F20,IF($K20=$L20,IF($E20=$K20,10,6),0),IF(OR($K20=$L20,SIGN($E20-$F20)<>SIGN($K20-$L20)),0,IF(AND($E20=$K20,$F20=$L20),10,IF(($E20-$F20)=($K20-$L20),6,IF(MAX($E20,$F20)=MAX($K20,$L20),5,IF(MIN($E20,$F20)=MIN($K20,$L20),4,3))))))) | N20: =IF(OR($K20="",$L20="",$G20="",$H20=""),"",IF(AND($G20=$K20,$H20=$L20),5+IF(($K20+$L20)>=6,2,IF(($K20+$L20)=5,1,0)),IF(AND($G20=$H20,$K20=$L20),3,IF(AND($G20<>$H20,$K20<>$L20,SIGN($G20-$H20)=SIGN($K20-$L20)),2,0)))) | O20: =IF(OR($K20="",$L20="",$I20="",$J20=""),"",IF(AND($I20=$K20,$J20=$L20),3,IF(SIGN($I20-$J20)=SIGN($K20-$L20),1,0)))
A21: C | B21: 15 | C21: BRA | D21: HAI | E21: 2 | F21: 0 | G21: 4 | H21: 1 | I21: 4 | J21: 0 | M21: =IF(OR($K21="",$L21="",$E21="",$F21=""),"",IF($E21=$F21,IF($K21=$L21,IF($E21=$K21,10,6),0),IF(OR($K21=$L21,SIGN($E21-$F21)<>SIGN($K21-$L21)),0,IF(AND($E21=$K21,$F21=$L21),10,IF(($E21-$F21)=($K21-$L21),6,IF(MAX($E21,$F21)=MAX($K21,$L21),5,IF(MIN($E21,$F21)=MIN($K21,$L21),4,3))))))) | N21: =IF(OR($K21="",$L21="",$G21="",$H21=""),"",IF(AND($G21=$K21,$H21=$L21),5+IF(($K21+$L21)>=6,2,IF(($K21+$L21)=5,1,0)),IF(AND($G21=$H21,$K21=$L21),3,IF(AND($G21<>$H21,$K21<>$L21,SIGN($G21-$H21)=SIGN($K21-$L21)),2,0)))) | O21: =IF(OR($K21="",$L21="",$I21="",$J21=""),"",IF(AND($I21=$K21,$J21=$L21),3,IF(SIGN($I21-$J21)=SIGN($K21-$L21),1,0)))
A22: C | B22: 16 | C22: ESC | D22: MAR | E22: 0 | F22: 2 | G22: 0 | H22: 2 | I22: 0 | J22: 1 | M22: =IF(OR($K22="",$L22="",$E22="",$F22=""),"",IF($E22=$F22,IF($K22=$L22,IF($E22=$K22,10,6),0),IF(OR($K22=$L22,SIGN($E22-$F22)<>SIGN($K22-$L22)),0,IF(AND($E22=$K22,$F22=$L22),10,IF(($E22-$F22)=($K22-$L22),6,IF(MAX($E22,$F22)=MAX($K22,$L22),5,IF(MIN($E22,$F22)=MIN($K22,$L22),4,3))))))) | N22: =IF(OR($K22="",$L22="",$G22="",$H22=""),"",IF(AND($G22=$K22,$H22=$L22),5+IF(($K22+$L22)>=6,2,IF(($K22+$L22)=5,1,0)),IF(AND($G22=$H22,$K22=$L22),3,IF(AND($G22<>$H22,$K22<>$L22,SIGN($G22-$H22)=SIGN($K22-$L22)),2,0)))) | O22: =IF(OR($K22="",$L22="",$I22="",$J22=""),"",IF(AND($I22=$K22,$J22=$L22),3,IF(SIGN($I22-$J22)=SIGN($K22-$L22),1,0)))
A23: C | B23: 17 | C23: ESC | D23: BRA | E23: 0 | F23: 2 | G23: 1 | H23: 4 | I23: 0 | J23: 2 | M23: =IF(OR($K23="",$L23="",$E23="",$F23=""),"",IF($E23=$F23,IF($K23=$L23,IF($E23=$K23,10,6),0),IF(OR($K23=$L23,SIGN($E23-$F23)<>SIGN($K23-$L23)),0,IF(AND($E23=$K23,$F23=$L23),10,IF(($E23-$F23)=($K23-$L23),6,IF(MAX($E23,$F23)=MAX($K23,$L23),5,IF(MIN($E23,$F23)=MIN($K23,$L23),4,3))))))) | N23: =IF(OR($K23="",$L23="",$G23="",$H23=""),"",IF(AND($G23=$K23,$H23=$L23),5+IF(($K23+$L23)>=6,2,IF(($K23+$L23)=5,1,0)),IF(AND($G23=$H23,$K23=$L23),3,IF(AND($G23<>$H23,$K23<>$L23,SIGN($G23-$H23)=SIGN($K23-$L23)),2,0)))) | O23: =IF(OR($K23="",$L23="",$I23="",$J23=""),"",IF(AND($I23=$K23,$J23=$L23),3,IF(SIGN($I23-$J23)=SIGN($K23-$L23),1,0)))
A24: C | B24: 18 | C24: MAR | D24: HAI | E24: 2 | F24: 0 | G24: 4 | H24: 1 | I24: 2 | J24: 0 | M24: =IF(OR($K24="",$L24="",$E24="",$F24=""),"",IF($E24=$F24,IF($K24=$L24,IF($E24=$K24,10,6),0),IF(OR($K24=$L24,SIGN($E24-$F24)<>SIGN($K24-$L24)),0,IF(AND($E24=$K24,$F24=$L24),10,IF(($E24-$F24)=($K24-$L24),6,IF(MAX($E24,$F24)=MAX($K24,$L24),5,IF(MIN($E24,$F24)=MIN($K24,$L24),4,3))))))) | N24: =IF(OR($K24="",$L24="",$G24="",$H24=""),"",IF(AND($G24=$K24,$H24=$L24),5+IF(($K24+$L24)>=6,2,IF(($K24+$L24)=5,1,0)),IF(AND($G24=$H24,$K24=$L24),3,IF(AND($G24<>$H24,$K24<>$L24,SIGN($G24-$H24)=SIGN($K24-$L24)),2,0)))) | O24: =IF(OR($K24="",$L24="",$I24="",$J24=""),"",IF(AND($I24=$K24,$J24=$L24),3,IF(SIGN($I24-$J24)=SIGN($K24-$L24),1,0)))
A25: Grupo D
A26: D | B26: 19 | C26: EUA | D26: PAR | E26: 2 | F26: 1 | G26: 1 | H26: 2 | I26: 0 | J26: 0 | M26: =IF(OR($K26="",$L26="",$E26="",$F26=""),"",IF($E26=$F26,IF($K26=$L26,IF($E26=$K26,10,6),0),IF(OR($K26=$L26,SIGN($E26-$F26)<>SIGN($K26-$L26)),0,IF(AND($E26=$K26,$F26=$L26),10,IF(($E26-$F26)=($K26-$L26),6,IF(MAX($E26,$F26)=MAX($K26,$L26),5,IF(MIN($E26,$F26)=MIN($K26,$L26),4,3))))))) | N26: =IF(OR($K26="",$L26="",$G26="",$H26=""),"",IF(AND($G26=$K26,$H26=$L26),5+IF(($K26+$L26)>=6,2,IF(($K26+$L26)=5,1,0)),IF(AND($G26=$H26,$K26=$L26),3,IF(AND($G26<>$H26,$K26<>$L26,SIGN($G26-$H26)=SIGN($K26-$L26)),2,0)))) | O26: =IF(OR($K26="",$L26="",$I26="",$J26=""),"",IF(AND($I26=$K26,$J26=$L26),3,IF(SIGN($I26-$J26)=SIGN($K26-$L26),1,0)))
A27: D | B27: 20 | C27: AUS | D27: TUR | E27: 2 | F27: 1 | G27: 2 | H27: 1 | I27: 1 | J27: 1 | M27: =IF(OR($K27="",$L27="",$E27="",$F27=""),"",IF($E27=$F27,IF($K27=$L27,IF($E27=$K27,10,6),0),IF(OR($K27=$L27,SIGN($E27-$F27)<>SIGN($K27-$L27)),0,IF(AND($E27=$K27,$F27=$L27),10,IF(($E27-$F27)=($K27-$L27),6,IF(MAX($E27,$F27)=MAX($K27,$L27),5,IF(MIN($E27,$F27)=MIN($K27,$L27),4,3))))))) | N27: =IF(OR($K27="",$L27="",$G27="",$H27=""),"",IF(AND($G27=$K27,$H27=$L27),5+IF(($K27+$L27)>=6,2,IF(($K27+$L27)=5,1,0)),IF(AND($G27=$H27,$K27=$L27),3,IF(AND($G27<>$H27,$K27<>$L27,SIGN($G27-$H27)=SIGN($K27-$L27)),2,0)))) | O27: =IF(OR($K27="",$L27="",$I27="",$J27=""),"",IF(AND($I27=$K27,$J27=$L27),3,IF(SIGN($I27-$J27)=SIGN($K27-$L27),1,0)))
A28: D | B28: 21 | C28: TUR | D28: PAR | E28: 2 | F28: 1 | G28: 1 | H28: 2 | I28: 1 | J28: 1 | M28: =IF(OR($K28="",$L28="",$E28="",$F28=""),"",IF($E28=$F28,IF($K28=$L28,IF($E28=$K28,10,6),0),IF(OR($K28=$L28,SIGN($E28-$F28)<>SIGN($K28-$L28)),0,IF(AND($E28=$K28,$F28=$L28),10,IF(($E28-$F28)=($K28-$L28),6,IF(MAX($E28,$F28)=MAX($K28,$L28),5,IF(MIN($E28,$F28)=MIN($K28,$L28),4,3))))))) | N28: =IF(OR($K28="",$L28="",$G28="",$H28=""),"",IF(AND($G28=$K28,$H28=$L28),5+IF(($K28+$L28)>=6,2,IF(($K28+$L28)=5,1,0)),IF(AND($G28=$H28,$K28=$L28),3,IF(AND($G28<>$H28,$K28<>$L28,SIGN($G28-$H28)=SIGN($K28-$L28)),2,0)))) | O28: =IF(OR($K28="",$L28="",$I28="",$J28=""),"",IF(AND($I28=$K28,$J28=$L28),3,IF(SIGN($I28-$J28)=SIGN($K28-$L28),1,0)))
A29: D | B29: 22 | C29: EUA | D29: AUS | E29: 1 | F29: 2 | G29: 1 | H29: 2 | I29: 0 | J29: 1 | M29: =IF(OR($K29="",$L29="",$E29="",$F29=""),"",IF($E29=$F29,IF($K29=$L29,IF($E29=$K29,10,6),0),IF(OR($K29=$L29,SIGN($E29-$F29)<>SIGN($K29-$L29)),0,IF(AND($E29=$K29,$F29=$L29),10,IF(($E29-$F29)=($K29-$L29),6,IF(MAX($E29,$F29)=MAX($K29,$L29),5,IF(MIN($E29,$F29)=MIN($K29,$L29),4,3))))))) | N29: =IF(OR($K29="",$L29="",$G29="",$H29=""),"",IF(AND($G29=$K29,$H29=$L29),5+IF(($K29+$L29)>=6,2,IF(($K29+$L29)=5,1,0)),IF(AND($G29=$H29,$K29=$L29),3,IF(AND($G29<>$H29,$K29<>$L29,SIGN($G29-$H29)=SIGN($K29-$L29)),2,0)))) | O29: =IF(OR($K29="",$L29="",$I29="",$J29=""),"",IF(AND($I29=$K29,$J29=$L29),3,IF(SIGN($I29-$J29)=SIGN($K29-$L29),1,0)))
A30: D | B30: 23 | C30: TUR | D30: EUA | E30: 2 | F30: 1 | G30: 2 | H30: 1 | I30: 2 | J30: 1 | M30: =IF(OR($K30="",$L30="",$E30="",$F30=""),"",IF($E30=$F30,IF($K30=$L30,IF($E30=$K30,10,6),0),IF(OR($K30=$L30,SIGN($E30-$F30)<>SIGN($K30-$L30)),0,IF(AND($E30=$K30,$F30=$L30),10,IF(($E30-$F30)=($K30-$L30),6,IF(MAX($E30,$F30)=MAX($K30,$L30),5,IF(MIN($E30,$F30)=MIN($K30,$L30),4,3))))))) | N30: =IF(OR($K30="",$L30="",$G30="",$H30=""),"",IF(AND($G30=$K30,$H30=$L30),5+IF(($K30+$L30)>=6,2,IF(($K30+$L30)=5,1,0)),IF(AND($G30=$H30,$K30=$L30),3,IF(AND($G30<>$H30,$K30<>$L30,SIGN($G30-$H30)=SIGN($K30-$L30)),2,0)))) | O30: =IF(OR($K30="",$L30="",$I30="",$J30=""),"",IF(AND($I30=$K30,$J30=$L30),3,IF(SIGN($I30-$J30)=SIGN($K30-$L30),1,0)))
A31: D | B31: 24 | C31: PAR | D31: AUS | E31: 1 | F31: 1 | G31: 1 | H31: 1 | I31: 0 | J31: 0 | M31: =IF(OR($K31="",$L31="",$E31="",$F31=""),"",IF($E31=$F31,IF($K31=$L31,IF($E31=$K31,10,6),0),IF(OR($K31=$L31,SIGN($E31-$F31)<>SIGN($K31-$L31)),0,IF(AND($E31=$K31,$F31=$L31),10,IF(($E31-$F31)=($K31-$L31),6,IF(MAX($E31,$F31)=MAX($K31,$L31),5,IF(MIN($E31,$F31)=MIN($K31,$L31),4,3))))))) | N31: =IF(OR($K31="",$L31="",$G31="",$H31=""),"",IF(AND($G31=$K31,$H31=$L31),5+IF(($K31+$L31)>=6,2,IF(($K31+$L31)=5,1,0)),IF(AND($G31=$H31,$K31=$L31),3,IF(AND($G31<>$H31,$K31<>$L31,SIGN($G31-$H31)=SIGN($K31-$L31)),2,0)))) | O31: =IF(OR($K31="",$L31="",$I31="",$J31=""),"",IF(AND($I31=$K31,$J31=$L31),3,IF(SIGN($I31-$J31)=SIGN($K31-$L31),1,0)))
A32: Grupo E
A33: E | B33: 25 | C33: CDM | D33: EQU | E33: 1 | F33: 1 | G33: 1 | H33: 1 | I33: 0 | J33: 0 | M33: =IF(OR($K33="",$L33="",$E33="",$F33=""),"",IF($E33=$F33,IF($K33=$L33,IF($E33=$K33,10,6),0),IF(OR($K33=$L33,SIGN($E33-$F33)<>SIGN($K33-$L33)),0,IF(AND($E33=$K33,$F33=$L33),10,IF(($E33-$F33)=($K33-$L33),6,IF(MAX($E33,$F33)=MAX($K33,$L33),5,IF(MIN($E33,$F33)=MIN($K33,$L33),4,3))))))) | N33: =IF(OR($K33="",$L33="",$G33="",$H33=""),"",IF(AND($G33=$K33,$H33=$L33),5+IF(($K33+$L33)>=6,2,IF(($K33+$L33)=5,1,0)),IF(AND($G33=$H33,$K33=$L33),3,IF(AND($G33<>$H33,$K33<>$L33,SIGN($G33-$H33)=SIGN($K33-$L33)),2,0)))) | O33: =IF(OR($K33="",$L33="",$I33="",$J33=""),"",IF(AND($I33=$K33,$J33=$L33),3,IF(SIGN($I33-$J33)=SIGN($K33-$L33),1,0)))
A34: E | B34: 26 | C34: ALE | D34: CUR | E34: 2 | F34: 0 | G34: 4 | H34: 1 | I34: 3 | J34: 0 | M34: =IF(OR($K34="",$L34="",$E34="",$F34=""),"",IF($E34=$F34,IF($K34=$L34,IF($E34=$K34,10,6),0),IF(OR($K34=$L34,SIGN($E34-$F34)<>SIGN($K34-$L34)),0,IF(AND($E34=$K34,$F34=$L34),10,IF(($E34-$F34)=($K34-$L34),6,IF(MAX($E34,$F34)=MAX($K34,$L34),5,IF(MIN($E34,$F34)=MIN($K34,$L34),4,3))))))) | N34: =IF(OR($K34="",$L34="",$G34="",$H34=""),"",IF(AND($G34=$K34,$H34=$L34),5+IF(($K34+$L34)>=6,2,IF(($K34+$L34)=5,1,0)),IF(AND($G34=$H34,$K34=$L34),3,IF(AND($G34<>$H34,$K34<>$L34,SIGN($G34-$H34)=SIGN($K34-$L34)),2,0)))) | O34: =IF(OR($K34="",$L34="",$I34="",$J34=""),"",IF(AND($I34=$K34,$J34=$L34),3,IF(SIGN($I34-$J34)=SIGN($K34-$L34),1,0)))
A35: E | B35: 27 | C35: ALE | D35: CDM | E35: 2 | F35: 0 | G35: 2 | H35: 0 | I35: 1 | J35: 0 | M35: =IF(OR($K35="",$L35="",$E35="",$F35=""),"",IF($E35=$F35,IF($K35=$L35,IF($E35=$K35,10,6),0),IF(OR($K35=$L35,SIGN($E35-$F35)<>SIGN($K35-$L35)),0,IF(AND($E35=$K35,$F35=$L35),10,IF(($E35-$F35)=($K35-$L35),6,IF(MAX($E35,$F35)=MAX($K35,$L35),5,IF(MIN($E35,$F35)=MIN($K35,$L35),4,3))))))) | N35: =IF(OR($K35="",$L35="",$G35="",$H35=""),"",IF(AND($G35=$K35,$H35=$L35),5+IF(($K35+$L35)>=6,2,IF(($K35+$L35)=5,1,0)),IF(AND($G35=$H35,$K35=$L35),3,IF(AND($G35<>$H35,$K35<>$L35,SIGN($G35-$H35)=SIGN($K35-$L35)),2,0)))) | O35: =IF(OR($K35="",$L35="",$I35="",$J35=""),"",IF(AND($I35=$K35,$J35=$L35),3,IF(SIGN($I35-$J35)=SIGN($K35-$L35),1,0)))
A36: E | B36: 28 | C36: EQU | D36: CUR | E36: 2 | F36: 0 | G36: 4 | H36: 1 | I36: 2 | J36: 0 | M36: =IF(OR($K36="",$L36="",$E36="",$F36=""),"",IF($E36=$F36,IF($K36=$L36,IF($E36=$K36,10,6),0),IF(OR($K36=$L36,SIGN($E36-$F36)<>SIGN($K36-$L36)),0,IF(AND($E36=$K36,$F36=$L36),10,IF(($E36-$F36)=($K36-$L36),6,IF(MAX($E36,$F36)=MAX($K36,$L36),5,IF(MIN($E36,$F36)=MIN($K36,$L36),4,3))))))) | N36: =IF(OR($K36="",$L36="",$G36="",$H36=""),"",IF(AND($G36=$K36,$H36=$L36),5+IF(($K36+$L36)>=6,2,IF(($K36+$L36)=5,1,0)),IF(AND($G36=$H36,$K36=$L36),3,IF(AND($G36<>$H36,$K36<>$L36,SIGN($G36-$H36)=SIGN($K36-$L36)),2,0)))) | O36: =IF(OR($K36="",$L36="",$I36="",$J36=""),"",IF(AND($I36=$K36,$J36=$L36),3,IF(SIGN($I36-$J36)=SIGN($K36-$L36),1,0)))
A37: E | B37: 29 | C37: CUR | D37: CDM | E37: 0 | F37: 2 | G37: 1 | H37: 4 | I37: 0 | J37: 2 | M37: =IF(OR($K37="",$L37="",$E37="",$F37=""),"",IF($E37=$F37,IF($K37=$L37,IF($E37=$K37,10,6),0),IF(OR($K37=$L37,SIGN($E37-$F37)<>SIGN($K37-$L37)),0,IF(AND($E37=$K37,$F37=$L37),10,IF(($E37-$F37)=($K37-$L37),6,IF(MAX($E37,$F37)=MAX($K37,$L37),5,IF(MIN($E37,$F37)=MIN($K37,$L37),4,3))))))) | N37: =IF(OR($K37="",$L37="",$G37="",$H37=""),"",IF(AND($G37=$K37,$H37=$L37),5+IF(($K37+$L37)>=6,2,IF(($K37+$L37)=5,1,0)),IF(AND($G37=$H37,$K37=$L37),3,IF(AND($G37<>$H37,$K37<>$L37,SIGN($G37-$H37)=SIGN($K37-$L37)),2,0)))) | O37: =IF(OR($K37="",$L37="",$I37="",$J37=""),"",IF(AND($I37=$K37,$J37=$L37),3,IF(SIGN($I37-$J37)=SIGN($K37-$L37),1,0)))
A38: E | B38: 30 | C38: EQU | D38: ALE | E38: 2 | F38: 1 | G38: 2 | H38: 1 | I38: 0 | J38: 0 | M38: =IF(OR($K38="",$L38="",$E38="",$F38=""),"",IF($E38=$F38,IF($K38=$L38,IF($E38=$K38,10,6),0),IF(OR($K38=$L38,SIGN($E38-$F38)<>SIGN($K38-$L38)),0,IF(AND($E38=$K38,$F38=$L38),10,IF(($E38-$F38)=($K38-$L38),6,IF(MAX($E38,$F38)=MAX($K38,$L38),5,IF(MIN($E38,$F38)=MIN($K38,$L38),4,3))))))) | N38: =IF(OR($K38="",$L38="",$G38="",$H38=""),"",IF(AND($G38=$K38,$H38=$L38),5+IF(($K38+$L38)>=6,2,IF(($K38+$L38)=5,1,0)),IF(AND($G38=$H38,$K38=$L38),3,IF(AND($G38<>$H38,$K38<>$L38,SIGN($G38-$H38)=SIGN($K38-$L38)),2,0)))) | O38: =IF(OR($K38="",$L38="",$I38="",$J38=""),"",IF(AND($I38=$K38,$J38=$L38),3,IF(SIGN($I38-$J38)=SIGN($K38-$L38),1,0)))
A39: Grupo F
A40: F | B40: 31 | C40: HOL | D40: JAP | E40: 1 | F40: 2 | G40: 1 | H40: 2 | I40: 1 | J40: 1 | M40: =IF(OR($K40="",$L40="",$E40="",$F40=""),"",IF($E40=$F40,IF($K40=$L40,IF($E40=$K40,10,6),0),IF(OR($K40=$L40,SIGN($E40-$F40)<>SIGN($K40-$L40)),0,IF(AND($E40=$K40,$F40=$L40),10,IF(($E40-$F40)=($K40-$L40),6,IF(MAX($E40,$F40)=MAX($K40,$L40),5,IF(MIN($E40,$F40)=MIN($K40,$L40),4,3))))))) | N40: =IF(OR($K40="",$L40="",$G40="",$H40=""),"",IF(AND($G40=$K40,$H40=$L40),5+IF(($K40+$L40)>=6,2,IF(($K40+$L40)=5,1,0)),IF(AND($G40=$H40,$K40=$L40),3,IF(AND($G40<>$H40,$K40<>$L40,SIGN($G40-$H40)=SIGN($K40-$L40)),2,0)))) | O40: =IF(OR($K40="",$L40="",$I40="",$J40=""),"",IF(AND($I40=$K40,$J40=$L40),3,IF(SIGN($I40-$J40)=SIGN($K40-$L40),1,0)))
...

Sheet Totais
A1: Placar de Pontos — Copa 2026
A2: Bolão | B2: Fase de Grupos | C2: Jogos pontuados
A3: Bolão do Zap | B3: =SUM('Fase de Grupos'!M:M) | C3: =COUNT('Fase de Grupos'!M:M)
A4: Bolão do Cli | B4: =SUM('Fase de Grupos'!N:N) | C4: =COUNT('Fase de Grupos'!N:N)
A5: Polla 26 | B5: =SUM('Fase de Grupos'!O:O) | C5: =COUNT('Fase de Grupos'!O:O)

Sheet Classificados
A1: Classificados para a 2a Fase - por Bolao
A2: Grupo | B2: Bolao do Zap | D2: Bolao do Cli | F2: Polla 26 | H2: Obs
B3: 1o | C3: 2o | D3: 1o | E3: 2o | F3: 1o | G3: 2o
A4: A | D4: MEX | E4: COR
A5: B | D5: CAN | E5: SUI
A6: C | D6: BRA | E6: MAR
A7: D | D7: PAR | E7: AUS
A8: E | D8: EQU | E8: ALE
A9: F | D9: HOL | E9: TUN
A10: G | D10: BEL | E10: IRA
A11: H | D11: ESP | E11: URU
A12: I | D12: FRA | E12: NOR
A13: J | D13: ARG | E13: AUT
A14: K | D14: POR | E14: COL
A15: L | D15: ING | E15: CRO

Sheet Legenda
A1: Legenda e Notas
A3: Estrutura
A4: Fase de Grupos | B4: 72 jogos. Colunas M/V = gols do mandante e do visitante no palpite de cada bolao.
A5: Bolao do Cli | B5: Palpites ja preenchidos a partir dos prints (12.06.2026).
A6: Bolao do Zap / Polla 26 | B6: Colunas em branco, a preencher.
A7: Resultado Real | B7: Preencher conforme os jogos acontecem.
A8: Pts Zap / Cli / Polla | B8: Reservado para pontuacao por jogo conforme a regra de cada bolao.
A9: Classificados | B9: 1o e 2o de cada grupo por bolao. Cli ja preenchido.
A10: Siglas | B10: AFS Africa do Sul, COR Coreia do Sul, CAT Catar, BOS Bosnia, CDM Costa do Marfim, EQU Equador, CUR Curacao, EGT Egito, CPV Cabo Verde, IRQ Iraque, AGL Argelia, JRD Jordania, RDC Rep. Dem. do Congo, UZB Uzbequistao, GAN Gana, PAN Panama.
A12: Pontuacao automatica | B12: Colunas M/N/O calculam sozinhas quando voce preenche Real (K/L).
A13: Bolao do Zap (grupos) | B13: Exato 10 | dif de gols 6 | gols do vencedor 5 | gols do perdedor 4 | so vencedor 3 | empate exato 10 | empate placar errado 6 | resto 0.
A14: Bolao do Cli (grupos) | B14: Exato 5 (+1 se 5 gols no total, +2 se 6+ gols) | empate certo placar errado 3 | vitoria certa placar errado 2 | resto 0.
A15: Polla 26 | B15: Placar exato 3 | so o vencedor/empate certo 1 | resto 0.
A16: Mata-mata | B16: Ainda nao consolidado. Zap dobra a tabela (exato 15, dif 9, gols venc 8, gols perd 6, so venc 5). Cli e Polla mantem os mesmos valores dos grupos.
